Workbook

Sheet CONCEPTOS
A2: ASPECTO | B2: MAXIMA | C2: INTERMEDIA | D2: BAJA
A3: Asunción de riesgos (0-8) | B3: Este aspecto es muy favorable en la consecución de sus objetivos empresariales, no obstante se recomienda cierta prudencia para que esta competencia no reste importancia a las demás | C3: Cuenta con una actitud suficiente para afrontar riesgos e incertidumbre propios de la actividad empresarial. Aún asi busque fortalecer esta competencia | D3: Sería aconsejable una actitud más elevada en este aspecto para así poder aprovechar más oportunidades de negocio
A4: Capacidad de negociación (0-6) | B4: Este aspecto es muy favorable en la consecución de sus objetivos empresariales, no obstante se recomienda cierta prudencia para que esta actitud no reste importancia a las demás | C4: Cuenta con habilidades suficientes para negociar teniendo como objetivo que las dos partes ganen. Aún asi busque fortalecer esta competencia | D4: En una negociación, sería aconsejable una actitud superior que le permita conseguir sus objetivos a la vez que preservar las relaciones personales con la otra parte.
A5: Confianza en sí mismo(0-8) | B5: La elevada confianza en sí mismo y en sus capacidades es un aspecto extremadamente favorable para la consecución de sus objetivos empresariales, no obstante se recomienda cierta prudencia para que esta actitud no reste importancia a las demás | C5: Interpretación del Test: (Rango de 4-6). Cuenta con una confianza en sí mismo y en sus habilidades suficiente para adaptarse a las necesidades del entorno y conseguir los objetivos empresariales marcados. Aún asi busque fortalecer esta competencia | D5: Un mayor control sobre sus emociones sería altamente beneficioso para alcanzar los objetivos empresariales propuestos
A6: Flexibilidad y adaptarse a cambios (0-8) | B6: Interpretación del Test: (Rango de 7-8). Este aspecto es muy favorable en la consecución de sus objetivos empresariales, no obstante se recomienda cierta prudencia para que esta competencia no reste importancia a las demás | C6: Su competencia en este aspecto parece suficiente para ser competitivos en el mercado empresarial. Aún asi busque fortalecer esta competencia | D6: Sería aconsejable una actitud superior y gozar de mayor capacidad en este sentido para así poder aprovechar más oportunidades de negocio
A7: Innovación y creatividad (0-10) | B7: Este aspecto es muy favorable en la consecución de sus objetivos empresariales, no obstante se recomienda cierta prudencia para que esta competencia no reste importancia a las demás | C7: Cuenta con habilidad suficiente para superar de manera innovadora los desafíos del entorno empresarial. Aún asi busque fortalecer esta competencia | D7: Sería aconsejable una actitud más elevada en este aspecto para procurar siempre la competitividad. Puede formarse y entrenarse en el tema
A8: Liderazgo de Equipos (0-6) | B8: Este aspecto es muy favorable en la consecución de sus objetivos empresariales, no obstante se recomienda cierta prudencia para que esta actitud no reste importancia a las demás. | C8: Cuenta con competencia suficiente para liderar un equipo de trabajo. Aún asi busque fortalecer esta competencia | D8: Sería necesario que esta habilidad fuese superior para responsabilizarse de un equipo de trabajo
A9: Tenacidad para el Trabajo (0-10) | B9: Su elevada actitud hacia el trabajo es un aspecto extremadamente favorable para la consecución de sus objetivos empresariales, no obstante se recomienda cierta prudencia para que esta actitud no reste importancia a las demás | C9: Cuenta con una actitud favorable hacia el trabajo lo que contribuirá de forma positiva a la consecución de sus metas empresariales | D9: Sería conveniente contar con una actitud superior, hacia su capapcidad y disposición de trabajo para responder de forma satisfactoria a las demandas de su proyecto empresarial
A11: Valoracion total (0-56) | B11: ¡Adelante con su proyecto!, su elevada capacidad emprendedora le augura el éxito | C11: Tiene recursos suficientes para poner en marcha su negocio. Busque fortalceer aquellos aspectos en donde se muestra mayor debilidad. Aún asi busque fortalecer esta competencia | D11: Sería conveniente reenfocar su carrera profesional hacia campos diferentes al autoempleo o buscar un socio con un mejor perfil emprendedor que lo acompañe en su proyecto
A19: CC
A20: TI
A21: CE
A22: PEP

Sheet Datos Aprendiz
A1: Regional | B1: HUILA
A2: Centro de Formación: | B2: Centro de la Industria la Empresa y los Servicios
A3: Nombre Formación Titulada: | B3: Analisis y desarrollo de software
A4: Ficha: | B4: 3413988
A5: Nombre y Apellidos completos: | B5: Fayber Estyben Díaz Tierradentro
A6: Tipo de documento de identidad: | B6: CC | C6: 1075795667
A7: Fecha: | B7: 46144
A8: Correo Electrónico Personal: | B8: diazfayber27@gmail.com
A12: Instrucciones iniciales de la evidencia:
A14: 1. Realice el test cualidades emprendedoras
A15: 2. Realice el ejercicio MATRIZ DOFA PERSONAL y haga un análisis de su perfil como emprendedor en el Word Anexo a esta evidencia

Sheet Test Cualidades
A1: =+#REF! -> #REF!
A3: TEST DE CUALIDADES EMPRENDEDORAS
A4: Tomado de: http://www.ildefe.es/ildefefront/frontIldefeAction.do?action=viewCategory&categoryName=Test+de+Evaluaci%F3n+de+Emprendedores&id=6261
A6: TEST DE EVALUACION DE EMPRENDEDORES
A8: Marque de forma objetiva con una X de acuerdo a lo que considera que se acomoda mas a su perfil en cada pregunta
A9: Preguntas | C9: A veces | D9: De acuerdo | H9: En desacuerdo
A10: 1. En una empresa hay que estar atento, siempre se están presentando nuevas oportunidades de negocio | C10: x | I10: =IF(C10="x",1,IF(D10="x",2,IF(H10="x",0,-1))) -> 1
A11: 2.Me identifico con la frase "El 90% del éxito se basa simplemente en insistir". | H11: x | I11: =IF(C11="x",1,IF(D11="x",2,IF(H11="x",0,-1))) -> 0
A12: 3. La toma de decisiones es un acto exlusivamente racional | D12: x | I12: =IF(C12="x",1,IF(D12="x",0,IF(H12="x",2,-1))) -> 0
A13: 4. No me gustan los imprevistos, prefiero saber cada día con qué me voy a encontrar | H13: x | I13: =IF(C13="x",1,IF(D13="x",0,IF(H13="x",2,-1))) -> 2
A14: 5. Un buen negociador solo tiene en cuenta sus intereses | F14: x | H14: x | I14: =IF(C14="x",1,IF(D14="x",0,IF(H14="x",2,-1))) -> 2
A15: 6. A menudo tengo la sensación de que lo que digo no se tiene mucho en cuenta | H15: x | I15: =IF(C15="x",1,IF(D15="x",0,IF(H15="x",2,-1))) -> 2
A16: 7. Me concentro con facilidad, y no me cuesta pasar de una tarea a otra | D16: x | I16: =IF(C16="x",1,IF(D16="x",2,IF(H16="x",0,-1))) -> 2
A17: 8. Tiendo a disfrutar con las personas y las situaciones nuevas | C17: x | I17: =IF(C17="x",1,IF(D17="x",2,IF(H17="x",0,-1))) -> 1
A18: 9. Me molesta tener que dedicar parte de mi tiempo libre a asuntos de la empresa. | D18: x | I18: =IF(C18="x",1,IF(D18="x",0,IF(H18="x",2,-1))) -> 0
A19: 10. Me suelen decir que "ponga los pies en el suelo", tengo mucha imaginación | C19: x | I19: =IF(C19="x",1,IF(D19="x",2,IF(H19="x",0,-1))) -> 1
A20: 11. Después de tomar una decisión, me preocupa mucho que ésta no sea la mejor | D20: x | I20: =IF(C20="x",1,IF(D20="x",0,IF(H20="x",2,-1))) -> 0
A21: 12. Muchos operarios para que trabajen, necesitan "mano dura" | C21: x | I21: =IF(C21="x",1,IF(D21="x",0,IF(H21="x",2,-1))) -> 1
A22: 13. Soy de los que piensan que los pequeños fracasos son peldaños hacia el éxito | D22: x | I22: =IF(C22="x",1,IF(D22="x",2,IF(H22="x",0,-1))) -> 2
A23: 14. En ocasiones sin saber por qué me siento tenso (a) | D23: x | I23: =IF(C23="x",1,IF(D23="x",0,IF(H23="x",2,-1))) -> 0
A24: 15. Me podrían criticar por faltarme siempre tiempo para escuchar a mis colaboradores | F24: x | H24: x | I24: =IF(C24="x",1,IF(D24="x",0,IF(H24="x",2,-1))) -> 2
A25: 16. Me gusta proponer nuevas formas de hacer las cosas. No soporto la rutina | C25: x | I25: =IF(C25="x",1,IF(D25="x",2,IF(H25="x",0,-1))) -> 1
A26: 17. No me resulta fácil ponerme en el lugar de la otra persona | H26: x | I26: =IF(C26="x",1,IF(D26="x",0,IF(H26="x",2,-1))) -> 2
A27: 18. Me entusiasma la idea de desarrollar un nuevo proyecto aunque ello suponga más trabajo | D27: x | I27: =IF(C27="x",1,IF(D27="x",2,IF(H27="x",0,-1))) -> 2
A28: 19. Soporto mal los cambios, me siento cómodo (a) con lo establecido | D28: x | I28: =IF(C28="x",1,IF(D28="x",0,IF(H28="x",2,-1))) -> 0
A29: 20. Prefiero actuar según el momento que invertir tiempo en planificar | F29: x | H29: x | I29: =IF(C29="x",1,IF(D29="x",0,IF(H29="x",2,-1))) -> 2
A30: 21. Me gusta trabajar sobre seguro y no correr riesgos por pequeños que éstos sean | D30: x | I30: =IF(C30="x",1,IF(D30="x",0,IF(H30="x",2,-1))) -> 0
A31: 22. Mis amigos me ven como a una persona con éxito | C31: x | I31: =IF(C31="x",1,IF(D31="x",2,IF(H31="x",0,-1))) -> 1
A32: 23. Si un método funciona no merece la pena cambiarlo | C32: x | I32: =IF(C32="x",1,IF(D32="x",0,IF(H32="x",2,-1))) -> 1
A33: 24. Ante una situación tensa con un colaborador tiendo a resolverla cuanto antes | D33: x | I33: =IF(C33="x",1,IF(D33="x",2,IF(H33="x",0,-1))) -> 2
A34: 25. Cuando me comprometo con algo, no escatimo ni esfuerzos ni tiempo para realizarlo | D34: x | I34: =IF(C34="x",1,IF(D34="x",2,IF(H34="x",0,-1))) -> 2
A35: 26. Antes de tomar una decisión, me gusta analizar la información y prever las consecuencias | D35: x | I35: =IF(C35="x",1,IF(D35="x",2,IF(H35="x",0,-1))) -> 2
A36: 27. Considero que los problemas solo tienen una solución posible | F36: x | H36: x | I36: =IF(C36="x",1,IF(D36="x",0,IF(H36="x",2,-1))) -> 2
A37: 28. En una negociación exitosa siempre hay una parte ganadora y otra perdedora | F37: x | H37: x | I37: =IF(C37="x",1,IF(D37="x",2,IF(H37="x",0,-1))) -> 0
A39: Area | B39: Concepto
A40: Asunción de riesgos | B40: =IF(I40>0,(I40/8),0) -> 0.25 | I40: =I12+I20+I30+I35 -> 2
A41: Capacidad de negociación | B41: =IF(I41>0,I41/6,0) -> 0.66666667 | I41: =I14+I26+I37 -> 4
A42: Confianza en sí mismo | B42: =IF(I42>0,I42/8,0) -> 0.625 | I42: =I15+I22+I23+I31 -> 5
A43: Flexibilidad y adaptarse a cambios | B43: =IF(I43>0,I43/8,0) -> 0.5 | I43: =I10+I13+I17+I28 -> 4
A44: Innovación y creatividad | B44: =IF(I44>0,I44/10,0) -> 0.7 | I44: =I19+I25+I27+I32+I36 -> 7
...
