Workbook

Sheet INSTRUCCIONES
A1: =+'1. Datos Aprendiz'!A1 -> Luiger Dalieth Ledezma Asprilla -- T.I -- 1105469704 -- Fayber Estyben Díaz Tierradentro -- CC -- 1075795667 -- -- -- -- Analisis y desarollo de software -- 3413988 -- TARDE -- HERRAMIENTA PEDAGÓGICA "IDEACIÓN, CARACTERIZACION Y ANALISIS PESTEL DE UNA IDEA DE NEGOCIO" CREADA PARA FORMACION EN EMPRENDIMIENTO DESARROLLADA POR: INSTRUCTOR ALEJANDRO DIAZ VIGENCIA 2025 V1.1 (Shortv)
A3: INSTRUCCIONES DE LA EVIDENCIA
A5: 1. Lea atentamente las instrucciones para realizar esta evidencia y comprender la temática de la actividad de aprendizaje propuesta.
A6: 2. Para el taller propuesto usted realizará las siguientes acciones:
B8: a. | C8: Siga atentamente las indicaciones del instructor.
B9: b. | C9: Llene las celdas únicamente las que están en COLOR AMARILLO
B10: c. | C10: Desarrolle Taller "Producto Y Servicio"
B11: d. | C11: Haga atenta lectura de los materiales de las hojas "Lectura e infografía"
B12: e. | C12: Realice el planteamiento del problema, necesidad u oportunidad
B13: f. | C13: Identifique alternativas de solución
B14: g. | C14: Tome decisión seleccionando una idea de negocio
B15: h. | C15: Realice el Análisis PESTEL
B16: i. | C16: Realice un análisis técnico y de mercado de su idea de negocios escogida

Sheet 1. Datos Aprendiz
A1: =+CONCATENATE(A8,C18,B8,C18,C8,C18,A9,C18,B9,C18,C9,C18,A10,C18,B10,C18,C10,C18,C12,C18,C13,C18,E13,C18,A24) -> Luiger Dalieth Ledezma Asprilla -- T.I -- 1105469704 -- Fayber Estyben Díaz Tierradentro -- CC -- 1075795667 -- -- -- -- Analisis y desarollo de software -- 3413988 -- TARDE -- HERRAMIENTA PEDAGÓGICA "IDEACIÓN, CARACTERIZACION Y ANALISIS PESTEL DE UNA IDEA DE NEGOCIO" CREADA PARA FORMACION EN EMPRENDIMIENTO DESARROLLADA POR: INSTRUCTOR ALEJANDRO DIAZ VIGENCIA 2025 V1.1 (Shortv)
A3: Diligencie únicamente las celdas en color AMARILLO
A4: Modelo de IDEACION, VALORACIÓN Y CARACTERIZACION de Idea Negocio de uso pedagógico Versión 1.0
A7: Nombres Y Apellidos Completos | B7: Tipo de ID | C7: Numero de Id | D7: Teléfono de contacto | E7: Correo Electrónico (Personal)
A8: Luiger Dalieth Ledezma Asprilla | B8: T.I | C8: 1105469704 | D8: 3142703700 | E8: luugerdalieth@gmail.com
A9: Fayber Estyben Díaz Tierradentro | B9: CC | C9: 1075795667 | D9: 3234689690 | E9: diazfayber27@gmail.com
A12: Formación Titulada: | C12: Analisis y desarollo de software
A13: Número de Ficha: | C13: 3413988 | D13: Jornada | E13: TARDE | F13: --
C18: --
A24: HERRAMIENTA PEDAGÓGICA "IDEACIÓN, CARACTERIZACION Y ANALISIS PESTEL DE UNA IDEA DE NEGOCIO" CREADA PARA FORMACION EN EMPRENDIMIENTO DESARROLLADA POR: INSTRUCTOR ALEJANDRO DIAZ VIGENCIA 2025 V1.1 (Shortv)
A26: CC | E26: JORNADA
A27: T.I | E27: MAÑANA
A28: C.E | E28: TARDE
A29: PTT | E29: NOCHE
E30: CONTRAJORNADA TARDE
E31: CONTRAJORNADA MAÑANA
E32: VIRTUAL

Sheet 2. Taller y Caso Analisis
A1: =+'1. Datos Aprendiz'!A1 -> Luiger Dalieth Ledezma Asprilla -- T.I -- 1105469704 -- Fayber Estyben Díaz Tierradentro -- CC -- 1075795667 -- -- -- -- Analisis y desarollo de software -- 3413988 -- TARDE -- HERRAMIENTA PEDAGÓGICA "IDEACIÓN, CARACTERIZACION Y ANALISIS PESTEL DE UNA IDEA DE NEGOCIO" CREADA PARA FORMACION EN EMPRENDIMIENTO DESARROLLADA POR: INSTRUCTOR ALEJANDRO DIAZ VIGENCIA 2025 V1.1 (Shortv)
A2: Taller: Productos y Servicios
A5: 1. | B5: Teniendo en cuenta las definiciones de producto y servicio, clasifique los siguientes ítems en cuales son productos y cuales son servicios:
A7: 1 | B7: Alimentos enlatados | F7: PRODUCTO
A8: 2 | B8: Artículos de aseo personal | F8: PRODUCTO
A9: 3 | B9: Asesoría financiera | F9: SERVICIO
A10: 4 | B10: Automóvil | F10: PRODUCTO
A11: 5 | B11: Bebidas embotelladas | F11: PRODUCTO
A12: 6 | B12: Cámara digital | F12: PRODUCTO
A13: 7 | B13: Clases de idiomas | F13: SERVICIO
A14: 8 | B14: Clases de yoga | F14: SERVICIO
A15: 9 | B15: Computadora portátil | F15: PRODUCTO
A16: 10 | B16: Consulta médica | F16: SERVICIO
A19: 4 | B19: ¿Qué características tienen los productos y/o servicios expuestos en este caso? (Tener en cuenta las definiciones que usted identificó en los puntos 1 y 2 de este taller)
B25: PRODUCTO
B26: SERVICIO

Sheet 3. Planteamiento Problema
A1: =+'1. Datos Aprendiz'!A1 -> Luiger Dalieth Ledezma Asprilla -- T.I -- 1105469704 -- Fayber Estyben Díaz Tierradentro -- CC -- 1075795667 -- -- -- -- Analisis y desarollo de software -- 3413988 -- TARDE -- HERRAMIENTA PEDAGÓGICA "IDEACIÓN, CARACTERIZACION Y ANALISIS PESTEL DE UNA IDEA DE NEGOCIO" CREADA PARA FORMACION EN EMPRENDIMIENTO DESARROLLADA POR: INSTRUCTOR ALEJANDRO DIAZ VIGENCIA 2025 V1.1 (Shortv)
A3: # | B3: IDENTIFIQUE TRES (3) IDEAS DE NEGOCIO (Cada Idea de Negocio DEBE SER DIFERENTE DE LA OTRA) Ejemplo: Un restaurante de comida italiana | C3: Para cada idea de negocio identifique el problema, necesidad u oportunidad a resolver (ver infografía: Identificar el Problema, DESCRIBIR EN UN PEQUEÑO PARRAFO DE AL MENOS 8 LINEAS) | D3: ¿Qué personas se ven afectados por el problema o necesidad? Describa brevemente | E3: ¿Con que frecuencia las personas afectada tienen este problema? Ejemplo: Diario, Mensual | F3: ¿Como solucionan las personas actualmente este problema?, o, ¿Qué deben hacer, o a dónde deben ir, las personas para solucionar este problema o necesidad? Justifique en un PÁRRAFO DE 3 LINEAS
A4: 1 | B4: Venta de componentes y repuestos de computadores | C4: Uno de los problemas mas grandes y la oportunidad que tenemos con esta idea de negocio es que la gente no conoce de proveedores y sitios en donde la venta de estos repuestos sea un poco mas economica que pedir por internet y con la misma calidad. Pudiendo nosotros brindarles un asesoramiento con respecto a dichos componentes y la entrega del componente sera inmediata. | D4: Las personas que se ven afectas por la problematica son los clientes cuando quieren cambiar un componente de su computador, actualizarlo mejorarlo o cambiarlo | E4: CADA 2 MESES | F4: Las personas afectadas actualmente solucionan esta problamática comprando productos por internet
A5: 2 | B5: Venta de repuesto de moto | C5: La falta o ausencia de repuestos que se acomoden al presupuesto de una persona comun dificulta la compra de esos repuestos por eso esta idea de negocio buscan brindar productos originales y otros mas economicos para que el cliente pueda comprar el producto o repuesto de su preferencia. | D5: Las personas que se ven afectadas por la problemática son personas que cuentan con una moto y no logran encontrar repuestos que se acomoden a su presupuesto y sus preferencias ya que hay clientes que prefieren repuestos baratos y otros prefieren repuestos originales. | E5: MENSUALMENTE | F5: Las personas afectadas actualmente solucionan esta problamática comprando respuestos no originales o baratos
A6: 3 | B6: Gimnasio orientado a fitness y crossfit | C6: La falta o ausencia de gimnasios que no se logran acomodar al presupuesto de una persona comun ya que hay muchos establecimientos de gimnasio que tienen costos muy elevados y esto hace que se les dificulte adquirir de esos servicios y facilitarle a los clientes ofreciendole de otros servicios mas accesibles para ellos | D6: Las personas que se ven afectadas por la problemática son personas con sobrepeso que desean empezar una vida saludable o con problemas de salud | E6: MENSUALMENTE | F6: Las personas afectadas actualmente solucionan esta problamática comprando una membresia para el gimnasio
C20: DIARIAMENTE
C21: SEMANALMENTE
C22: QUINCENALMENTE
C23: MENSUALMENTE
C24: CADA 2 MESES
C25: CADA 3 MESES
C26: CADA 4 MESES
C27: CADA 6 MESES
C28: ANUALMENTE

Sheet 4. Opciones de Solucion
A1: =+'3. Planteamiento Problema'!A1 -> Luiger Dalieth Ledezma Asprilla -- T.I -- 1105469704 -- Fayber Estyben Díaz Tierradentro -- CC -- 1075795667 -- -- -- -- Analisis y desarollo de software -- 3413988 -- TARDE -- HERRAMIENTA PEDAGÓGICA "IDEACIÓN, CARACTERIZACION Y ANALISIS PESTEL DE UNA IDEA DE NEGOCIO" CREADA PARA FORMACION EN EMPRENDIMIENTO DESARROLLADA POR: INSTRUCTOR ALEJANDRO DIAZ VIGENCIA 2025 V1.1 (Shortv)
A3: IDENTIFICACIÓN DE ALTERNATIVAS DE SOLUCIÓN
A5: Idea de Negocio a considerar | B5: Problema (o la Oportunidad) Identificado | C5: Proponga para cada problema identificado, UNA posible solución | D5: Describa brevemente el valor agregado o innovación que podría aporta a cada solución: | E5: Cual es el Modelo de Negocio identificado en la solución
A6: =+'3. Planteamiento Problema'!B4 -> Venta de componentes y repuestos de computadores | B6: =+'3. Planteamiento Problema'!C4 -> Uno de los problemas mas grandes y la oportunidad que tenemos con esta idea de negocio es que la gente no conoce de proveedores y sitios en donde la venta de estos repuestos sea un poco mas economica que pedir por internet y con la misma calidad. Pudiendo nosotros brindarles un asesoramiento con respecto a dichos componentes y la entrega del componente sera inmediata. | C6: La solución a esta problemática es que con nosotros sabran un lugar de repuestos que se acomode a su presupuesto, podremos brindarle un asesoramiento de como se usa ese repuesto y le haremos entrega inmediata de ese producto segun lo que requiere el cliente. | D6: El valor agregado que esta solucion ofrece es que pueden comprar productos menos costosos y con la misma calidad. | E6: Tienda de electrónica: Venta de dispositivos electrónicos.
A7: =+'3. Planteamiento Problema'!B5 -> Venta de repuesto de moto | B7: =+'3. Planteamiento Problema'!C5 -> La falta o ausencia de repuestos que se acomoden al presupuesto de una persona comun dificulta la compra de esos repuestos por eso esta idea de negocio buscan brindar productos originales y otros mas economicos para que el cliente pueda comprar el producto o repuesto de su preferencia. | C7: La solución a esta problemática es que sabran de nosotros como un proveedor confiable en donde podran conseguir repuestos originales o de otra calidad. | D7: El valor agregado que esta solucion ofrece es que tendremos precios competitivos que se puedan acomodar al precio del cliente y poder brindarle un asesoramiento de dicho repuesto | E7: Distribuidor: Conexión entre fabricantes y minoristas.
A8: =+'3. Planteamiento Problema'!B6 -> Gimnasio orientado a fitness y crossfit | B8: =+'3. Planteamiento Problema'!C6 -> La falta o ausencia de gimnasios que no se logran acomodar al presupuesto de una persona comun ya que hay muchos establecimientos de gimnasio que tienen costos muy elevados y esto hace que se les dificulte adquirir de esos servicios y facilitarle a los clientes ofreciendole de otros servicios mas accesibles para ellos | C8: La solución a esta problemática es que nosotros como un gimnasio brindaremos una membresia mensual y no haremos cobros de otros servicios que se pueda dificultar para ellos. | D8: El valor agregado que esta solucion ofrece es no hacer cobros por servicios que deberian de ir incluida | E8: Membresías de gimnasios/clubes: Acceso a instalaciones y servicios mediante suscripción.
A10: RECOMENDACIONES
A12: 1. Pasión y interés: Elige una idea que te apasione y te interese.
A13: 2. Mercado y demanda: Identifica un mercado con demanda y crecimiento potencial.
A14: 3. Competencia: Analiza la competencia y busca una ventaja competitiva.
A15: 4. Recursos y habilidades: Asegúrate de tener los recursos y habilidades necesarios.
A16: 5. Inversión y financiamiento: Evalúa la inversión inicial y las opciones de financiamiento.
A17: 6. Riesgos y desafíos: Identifica los riesgos y desafíos potenciales.
A18: 7. Escalabilidad y crecimiento: Elige una idea con potencial de crecimiento y escalabilidad.
A19: 8. Innovación y diferenciación: Busca una idea innovadora y diferenciada.
A20: 9. Modelo de negocio: Define un modelo de negocio claro y sostenible.
A21: 10. Planificación y estrategia: Desarrolla un plan de negocio y estrategia efectiva.
A22: 11. Análisis de mercado y tendencias: Investiga el mercado y las tendencias actuales.
... A24: 13. Flexibilidad y adaptabilidad: Elige una idea que te permita adaptarte a cambios y tendencias.
B30: Agencia de viajes: Servicios de planificación y reserva de viajes.
B31: Biotecnología: Desarrollo de productos y servicios basados en biotecnología.
B32: Blockchain: Desarrollo de soluciones basadas en blockchain.
B33: Cafetería: Servicio de café y otros productos similares.
B34: Cajas de suscripción: Envío periódico de productos seleccionados.
B35: Comida a domicilio: Servicio de entrega de comida desde restaurantes.
B36: Consultoría: Prestación de servicios de asesoramiento especializado.
B37: Consultorio médico: Servicios de atención médica.
B38: Cuidado de mascotas: Servicios de cuidado y atención para mascotas.
B39: Despacho de abogados: Servicios legales.
B40: Distribuidor: Conexión entre fabricantes y minoristas.
B41: Drones: Aplicaciones para diversos sectores (logística, agricultura, etc.).
... B101: Tienda minorista: Venta de productos al consumidor final.

Sheet 5. Toma de Decision
A1: =+'4. Opciones de Solucion'!A1 -> Luiger Dalieth Ledezma Asprilla -- T.I -- 1105469704 -- Fayber Estyben Díaz Tierradentro -- CC -- 1075795667 -- -- -- -- Analisis y desarollo de software -- 3413988 -- TARDE -- HERRAMIENTA PEDAGÓGICA "IDEACIÓN, CARACTERIZACION Y ANALISIS PESTEL DE UNA IDEA DE NEGOCIO" CREADA PARA FORMACION EN EMPRENDIMIENTO DESARROLLADA POR: INSTRUCTOR ALEJANDRO DIAZ VIGENCIA 2025 V1.1 (Shortv)
A2: TOMA DE DECISIÓN
B4: De 1 a 5 escoja según su nivel de aceptación (siendo 1 el más BAJO y 5 el más ALTO) de cada una de las preguntas en cada Idea de Negocio a considerar
A5: Modelo De Negocio | B5: ¿Puedo ganar dinero con esta idea? ¿Representa una oportunidad de Negocio? | C5: ¿Qué tanto interés me genera esta Idea de Negocio? | D5: Para cada una de las Ideas de Negocio; ¿Es algo que la gente compra actualmente? | E5: ¿Existen muchos Competidores en el Mercado? (Investigue en internet) | F5: ¿Tengo las habilidades, capacidades para desarrollar esta Idea de Negocio? (o las puedo desarrollar en menos de 9 meses) | G5: ¿Puedo lograr conseguir recursos o acceder a fuentes de financiaón para esta Idea de Negocio? | H5: ¿Puede esta Idea de Negocio tener potencial de crecer en el tiempo? | I5: Con la Idea de Negocio ¿Me puedo diferenciar de los competidores actuales? | J5: ¿Existe la tecnología para desarrollar este Negocio?
A6: =+'4. Opciones de Solucion'!E6 -> Tienda de electrónica: Venta de dispositivos electrónicos. | B6: 5 | C6: 5 | D6: 5 | E6: 5 | F6: 4 | G6: 2 | H6: 5 | I6: 4 | J6: 5
A7: =+'4. Opciones de Solucion'!E7 -> Distribuidor: Conexión entre fabricantes y minoristas. | B7: 5 | C7: 4 | D7: 5 | E7: 5 | F7: 3 | G7: 1 | H7: 4 | I7: 3 | J7: 3
A8: =+'4. Opciones de Solucion'!E8 -> Membresías de gimnasios/clubes: Acceso a instalaciones y servicios mediante suscripción. | B8: 3 | C8: 2 | D8: 2 | E8: 4 | F8: 3 | G8: 1 | H8: 3 | I8: 2 | J8: 4
A11: Modelo De Negocio | B11: =+B5 -> ¿Puedo ganar dinero con esta idea? ¿Representa una oportunidad de Negocio? | C11: =+C5 -> ¿Qué tanto interés me genera esta Idea de Negocio? | D11: =+D5 -> Para cada una de las Ideas de Negocio; ¿Es algo que la gente compra actualmente? | E11: =+E5 -> ¿Existen muchos Competidores en el Mercado? (Investigue en internet) | F11: =+F5 -> ¿Tengo las habilidades, capacidades para desarrollar esta Idea de Negocio? (o las puedo desarrollar en menos de 9 meses) | G11: =+G5 -> ¿Puedo lograr conseguir recursos o acceder a fuentes de financiaón para esta Idea de Negocio? | H11: =+H5 -> ¿Puede esta Idea de Negocio tener potencial de crecer en el tiempo? | I11: =+I5 -> Con la Idea de Negocio ¿Me puedo diferenciar de los competidores actuales? | J11: =+J5 -> ¿Existe la tecnología para desarrollar este Negocio?
A12: Peso decisión: | B12: 5 | C12: 5 | D12: 4 | E12: 4 | F12: 3 | G12: 3 | H12: 2 | I12: 2 | J12: 1
A15: Modelo De Negocio | B15: =+B11 -> ¿Puedo ganar dinero con esta idea? ¿Representa una oportunidad de Negocio? | C15: =+C11 -> ¿Qué tanto interés me genera esta Idea de Negocio? | D15: =+D11 -> Para cada una de las Ideas de Negocio; ¿Es algo que la gente compra actualmente? | E15: =+E11 -> ¿Existen muchos Competidores en el Mercado? (Investigue en internet) | F15: =+F11 -> ¿Tengo las habilidades, capacidades para desarrollar esta Idea de Negocio? (o las puedo desarrollar en menos de 9 meses) | G15: =+G11 -> ¿Puedo lograr conseguir recursos o acceder a fuentes de financiaón para esta Idea de Negocio? | H15: =+H11 -> ¿Puede esta Idea de Negocio tener potencial de crecer en el tiempo? | I15: =+I11 -> Con la Idea de Negocio ¿Me puedo diferenciar de los competidores actuales? | J15: =+J11 -> ¿Existe la tecnología para desarrollar este Negocio? | K15: TOTAL
A16: =+A6 -> Tienda de electrónica: Venta de dispositivos electrónicos. | B16: =+B6*B12 -> 25 | C16: =+C6*C12 -> 25 | D16: =+D6*D12 -> 20 | E16: =+E6*E12 -> 20 | F16: =+F6*F12 -> 12 | G16: =+G6*G12 -> 6 | H16: =+H6*H12 -> 10 | I16: =+I6*I12 -> 8 | J16: =+J6*J12 -> 5 | K16: =+SUM(B16:J16) -> 131
A17: =+A7 -> Distribuidor: Conexión entre fabricantes y minoristas. | B17: =+B7*B12 -> 25 | C17: =+C7*C12 -> 20 | D17: =+D7*D12 -> 20 | E17: =+E7*E12 -> 20 | F17: =+F7*F12 -> 9 | G17: =+G7*G12 -> 3 | H17: =+H7*H12 -> 8 | I17: =+I7*I12 -> 6 | J17: =+J7*J12 -> 3 | K17: =+SUM(B17:J17) -> 114
A18: =+A8 -> Membresías de gimnasios/clubes: Acceso a instalaciones y servicios mediante suscripción. | B18: =+B8*B12 -> 15 | C18: =+C8*C12 -> 10 | D18: =+D8*D12 -> 8 | E18: =+E8*E12 -> 16 | F18: =+F8*F12 -> 9 | G18: =+G8*G12 -> 3 | H18: =+H8*H12 -> 6 | I18: =+I8*I12 -> 4 | J18: =+J8*J12 -> 4 | K18: =+SUM(B18:J18) -> 75
A21: Modelo de Negocio Escogido: | B21: =+IF(MAX(K16:K18)=K16,A16,IF(MAX(K16:K18)=K17,A17,IF(MAX(K16:K18)=K18,A18,"EMPATE POR FAVOR ELEGIR UNA IDEA"))) -> Tienda de electrónica: Venta de dispositivos electrónicos.
A22: Idea de Negocio Escogida: | B22: =IF(B21=A6,'4. Opciones de Solucion'!A6,IF(OR(B21='5. Toma de Decision'!A7,C21='5. Toma de Decision'!A7,D21='5. Toma de Decision'!A7,E21='5. Toma de Decision'!A7),'4. Opciones de Solucion'!A7,IF(OR(B21='5. Toma de Decision'!A8,C21='5. Toma de Decision'!A8,D21='5. Toma de Decision'!A8,E21='5. Toma de Decision'!A8),'4. Opciones de Solucion'!A8,"EMPATE"))) -> Venta de componentes y repuestos de computadores
D30: 1
D31: 2
D32: 3
D33: 4
D34: 5

Sheet 6. ANALISIS PESTEL
A1: =+'5. Toma de Decision'!A1 -> Luiger Dalieth Ledezma Asprilla -- T.I -- 1105469704 -- Fayber Estyben Díaz Tierradentro -- CC -- 1075795667 -- -- -- -- Analisis y desarollo de software -- 3413988 -- TARDE -- HERRAMIENTA PEDAGÓGICA "IDEACIÓN, CARACTERIZACION Y ANALISIS PESTEL DE UNA IDEA DE NEGOCIO" CREADA PARA FORMACION EN EMPRENDIMIENTO DESARROLLADA POR: INSTRUCTOR ALEJANDRO DIAZ VIGENCIA 2025 V1.1 (Shortv)
A2: HERRAMIENTA ANALISIS PESTEL PARA UN NEGOCIO
B3: Para el sector: | E3: SECTOR TERCEARIO
B4: Actividad Económica | E4: Comercio electrónico y marketplaces
B5: Modelo de Negocio escogido | E5: =+'5. Toma de Decision'!B21 -> Tienda de electrónica: Venta de dispositivos electrónicos.
B6: Idea de Negocio Escogida: | E6: =+'5. Toma de Decision'!B22 -> Venta de componentes y repuestos de computadores
B8: CRITERIO | E8: DESCRIPCIÓN | F8: IMPACTO (Riesgo/Oportunidad) | G8: NIVEL DE IMPACTO
B9: P | C9: POLITICO | D9: P1 | E9: ¿Existe corrupción en la zona geográfica donde se dearrollará la idea de Negocio?
D10: P1 | E10: ¿Existen garantías de seguridad u orden público, por parte del gobierno (municipal, departamental o nacional) para desarrollar la Idea de Negocio? | F10: OPORTUNIDAD | G10: ALTO
B11: E | C11: ECONÓMICO | D11: E1 | E11: El sector económico de la idea de negocios propuesta por usted, presenta un crecimiento (Las ventas del sector estan en crecimiento)
D12: E2 | E12: El costo de materia prima e insumos de producción en el sector económico de la idea de negocios se ha incrementado
D13: E1 | E13: Hay mucha competencia en el sector de la idea de negocios por parte de muchos competidores | F13: RIESGO O AMENAZA | G13: ALTO
B14: S | C14: SOCIAL | D14: S1 | E14: ¿La opinión de las personas con respecto a la idea de negocio propuesto es buena y aceptada por los posibles clientes? | F14: OPORTUNIDAD | G14: ALTO
B15: T | C15: TECNOLÓGICO | D15: T1 | E15: La fácil adopción de nuevas tecnologías por parte de posibles compradores o clientes
D16: T1 | E16: Es fácil comprar las máquinas, herramientas y equipos para desarrollar la idea de negocio (¿no hay que importarlas fuera del departamento o el país?) | F16: OPORTUNIDAD | G16: ALTO
D17: T2 | E17: Es fácil comprar las materias primas e insumos, para desarrollar la idea de negocio (no hay que importarlas fuera del departamento o el país) | F17: RIESGO O AMENAZA | G17: MEDIO
D18: T3 | E18: ¿Existe fácil acceso y buena cobertura de internet en el área donde se encuentran sus posibles clientes? | F18: OPORTUNIDAD | G18: ALTO
B19: E | C19: ECOLÓGICO | D19: E1 | E19: El clima - Fenómeno del Niño(a) ¿pone en riesgo el desarrollo de su idea de negocios? | F19: RIESGO O AMENAZA | G19: ALTO
D20: E2 | E20: Las materias prima o insumos que se requieren para iniciar su negocio ¿Afectan el medio ambiente? | F20: OPORTUNIDAD | G20: MEDIO
B21: L | C21: LEGAL | D21: L1 | E21: ¿Existe normatividad Legal adversa o difícil de cumplir, para poner en marcha su emprendimiento? | F21: RIESGO O AMENAZA | G21: MEDIO
B26: P | C26: POLÍTICO | D26: P1 | E26: Estabilidad política
D27: P2 | E27: Política fiscal
D28: P3 | E28: Seguridad jurídica
D29: P4 | E29: Corrupción
D30: P5 | E30: Contrabando
D31: P6 | E31: Informalidad
D32: P7 | E32: Sistema del gobierno
D33: P8 | E33: Defensa a la libre competencia
D34: P9 | E34: Respeto por la propiedad privada
D35: P10 | E35: Política de inversión del Estado
D36: P11 | E36: Respeto por la propiedad intelectual
D37: P12 | E37: Seguridad y orden interno
D38: P13 | E38: Relación con otros países
... D40: P15 | E40: Relaciones con organismos internacionales
B41: E | C41: ECONÓMICO | D41: E1 | E41: PBI nacional
D42: E2 | E42: PBI per cápita
D43: E3 | E43: Tasa de interés
D44: E4 | E44: Tasa de inflación
D45: E5 | E45: Costo de mano de obra
D46: E6 | E46: Costo de materia prima
...

Sheet 7. Taller# 2
A1: =+'6. ANALISIS PESTEL'!A1 -> Luiger Dalieth Ledezma Asprilla -- T.I -- 1105469704 -- Fayber Estyben Díaz Tierradentro -- CC -- 1075795667 -- -- -- -- Analisis y desarollo de software -- 3413988 -- TARDE -- HERRAMIENTA PEDAGÓGICA "IDEACIÓN, CARACTERIZACION Y ANALISIS PESTEL DE UNA IDEA DE NEGOCIO" CREADA PARA FORMACION EN EMPRENDIMIENTO DESARROLLADA POR: INSTRUCTOR ALEJANDRO DIAZ VIGENCIA 2025 V1.1 (Shortv)
A3: TALLER IDENTIFICACION DE PRODUCTOS O SEVICIOS EN UN NEGOCIO
A5: Observe detenidamente cada una de las imágenes y desarrolle el taller que se encuentra al final de esta sección
A61: 1. Identifique 5 productos que venda este negocio
C94: 1 | D94: Bonyurt
C95: 2 | D95: Pan
C96: 3 | D96: Bolsa de leche
C97: 4 | D97: Rebanadas de torta
C98: 5 | D98: Queso
A102: Identifique 5 productos que venda este negocio
C135: 1 | D135: Lapiceros
C136: 2 | D136: Cartulinas
C137: 3 | D137: Marcadores
C138: 4 | D138: Cintas
C139: 5 | D139: Colbon
A142: Identifique 5 productos que venda este negocio
C175: 1 | D175: Capuchino
C176: 2 | D176: Cacao
C177: 3 | D177: Cafe
C178: 4 | D178: Cafe express
C179: 5 | D179: Cafe con leche
A182: Identifique 5 productos que venda este negocio
C215: 1 | D215: Parlantes
C216: 2 | D216: Audifonos
C217: 3 | D217: Tablets
C218: 4 | D218: Celulares
C219: 5 | D219: Humidificador
A222: Identifique 5 servicios que venda este negocio
C255: 1 | D255: Peliculas
C256: 2 | D256: Series
C257: 3 | D257: Red wifi
C258: 4 | D258: Canales de TV
C259: 5 | D259: Deportes
A262: Identifique 5 servicios que venda este negocio
C295: 1 | D295: Asesoria financiera
C296: 2 | D296: CDT
C297: 3 | D297: Cuenta de ahorro
C298: 4 | D298: Cuenta de credito
C299: 5 | D299: Cajero automatico
A302: Identifique 5 servicios que venda este negocio
...

Sheet 8. Analisis Idea
A1: =+'7. Taller# 2'!A1 -> Luiger Dalieth Ledezma Asprilla -- T.I -- 1105469704 -- Fayber Estyben Díaz Tierradentro -- CC -- 1075795667 -- -- -- -- Analisis y desarollo de software -- 3413988 -- TARDE -- HERRAMIENTA PEDAGÓGICA "IDEACIÓN, CARACTERIZACION Y ANALISIS PESTEL DE UNA IDEA DE NEGOCIO" CREADA PARA FORMACION EN EMPRENDIMIENTO DESARROLLADA POR: INSTRUCTOR ALEJANDRO DIAZ VIGENCIA 2025 V1.1 (Shortv)
A3: CARACTERIZACION IDEA DE NEGOCIO
A5: Nombre Idea de Negocios (como lo conocerán sus clientes en el comercio): | D5: CompuTech
A6: Nombre Idea de Negocios que escogió: | D6: =+'6. ANALISIS PESTEL'!E6 -> Venta de componentes y repuestos de computadores
A8: MODELO DE NEGOCIO | B8: PRODUCTOS O SERVICIOS A OFRECER | D8: VALOR AGREGADO (O INNOVACION) | E8: PERSONAL TECNICO REQUERIDO (A quien hay que contratar en el emprendimiento, identifique cargos o funciones a cumplir por parte del personal talento humano) | F8: PRINCIPALES COMPETIDORES DIRECTOS (¿Quiénes son las empresas que competirán en el mercado con su negocio?, nombre 3) | G8: PROVEEDORES DE MATERIAS PRIMAS, INSUMOS o INVENTARIOS DE PRODUCTOS TERMINADOS PARA LA VENTA | H8: ESTRATEGIAS DE COMUNICACIÓN Y PROMOCIÓN (Redes Sociales, marketing digital)
A9: =+'5. Toma de Decision'!B21 -> Tienda de electrónica: Venta de dispositivos electrónicos. | B9: 1 | C9: Nombre Producto o Servicio | D9: Al haber una escases de RAM y un auomento excesivo haremos lo posible para vender la RAM a un precio menor comparado con la oferta que hay en el mercado. | E9: Administrador(Dueño): Se encargara de que se empleen bien las funciones de los demas trabajadores y puede encargarse con la estrategia de comunicacion. Tecnicos de sistemas o de computo: Que se encarguen de vender y orientar a los clientes sobre lo que pueden comprar. Auxiliar de almacen: Se encargara de llevar el conteo de inventario debe llevar un control estricto de las existencias, organizar los repuestos por referencia y reponer lo que se agote rápidamente. | F9: Los posibles competidores podrian ser los negocios que se situan en la zona de comuneros como: Alphanet, Iphone store, TuConsultorTI. | G9: Los provedores que contariamos para la obtecion de repuestos serian: Kingston, Fury, ADATA, Samsung, MSI y Corsair | H9: Usar redes sociales estrategicas utilizando tiktok,instagram y facebook para utiilizar los reels y generar videos de un impacto inmediato diciendo las promociones que tengamos. Usar de whatsapp como un medio de comunicacion directa. Usando plataformas de mercado digital como Facebook Marketplace y MercadoLibre para publicar repuestos para que hagan compra de ello.
C10: Memoria RAM
C11: Características Técnicas
C12: El producto o servicio tiene las siguientes caracteristicas tecnicas: es un chip que ayuda a aumentar la velocidad del computador, el tamaño varia segun la version ya que vienen en 2 tipos que son DDR4 y DDR5.
C13: Materia Prima e Insumos requeridos
C14: El negocio consiste en ser proveedores las marcas proveedoras son: Samsung electronics, kingston, fury, y ADATA,
C15: Descripción proceso de fabricación o de servicio:
C16: El proceso de la fabricacion de la memoria RAM consiste mediante procesos avanzados de semiconductores en salas limpias.
B17: 2 | C17: Nombre Producto o Servicio | D17: Hay un creciente aumento en los precios de los discos haremos que los precios de los discos mantengan un precio menor con la oferta en el mercado.
C18: Disco SSD
C19: Características Técnicas
C20: El producto tiene como caracteristicas ser de una forma cuadrada, trabaja con chips integrados y tiene diferentes tamaños de almacenamiento,
C21: Materia Prima e Insumos requeridos
C22: Los provedores de estos discos SSD son: ADATA, samsung, y kingston.
C23: Descripción proceso de fabricación o de servicio:
C24: EL proceso de fabricación consiste en los siguientes pasos: consiste en la creación de obleas de silicio para los chips de memoria flash NAND.
B25: 3 | C25: Nombre Producto o Servicio | D25: Hay un creciente aumento en los precios de los discos haremos que los precios de los discos mantengan un precio menor con la oferta en el mercado.
C26: Disco M.2
C27: Características Técnicas
C28: El producto o servicio tiene las siguientes caracteristicas su forma es larga delgada o pequeña y delgada y tiene diferentes tamaños de almacenamiento.
C29: Materia Prima e Insumos requeridos
C30: Los proveedores de estos discos M.2 son: Samsung, Kingston, MSI Y ADATA
C31: Descripción proceso de fabricación o de servicio:
C32: EL proceso de fabricación consiste en los siguientes pasos: implica el diseño de la placa (PCB), el montaje automatizado mediante tecnología SMT (soldadura de componentes como controladoras y NAND flash).
B33: 4 | C33: Nombre Producto o Servicio | D33: Con el proximo aumento de las memorias USB haremos lo posible por mantener el precio o dar ofertas con respecto a ellas.
C34: Memorias USB:
C35: Características Técnicas
C36: El producto o servicio tiene las siguientes caracteristicas su forma es pequeña y delgadita y faciles de cargar y con diferentes tamaños de almacenamiento
C37: Materia Prima e Insumos requeridos
C38: Consta de 4 fases principales: diseño, montaje superficial (SMT), depanelización y pruebas exhaustivas de control de calidad.
C39: Descripción proceso de fabricación o de servicio:
C40: Los proveedores de memorias USB serian:Kingston, SanDisk, corsair, y ADATA.
B41: 5 | C41: Nombre Producto o Servicio | D41: Con las tarjetas graficas haremos que las personas que los compren reciban un certificado para su garantia por cierto tiempo y trataremos de dar precios competitivos
C42: Tarjeta grafica
C43: Características Técnicas
...

Sheet Resumen
A1: =+'1. Datos Aprendiz'!A1 -> Luiger Dalieth Ledezma Asprilla -- T.I -- 1105469704 -- Fayber Estyben Díaz Tierradentro -- CC -- 1075795667 -- -- -- -- Analisis y desarollo de software -- 3413988 -- TARDE -- HERRAMIENTA PEDAGÓGICA "IDEACIÓN, CARACTERIZACION Y ANALISIS PESTEL DE UNA IDEA DE NEGOCIO" CREADA PARA FORMACION EN EMPRENDIMIENTO DESARROLLADA POR: INSTRUCTOR ALEJANDRO DIAZ VIGENCIA 2025 V1.1 (Shortv)
A3: DATOS DEL EQUIPO DE TRABAJO
A5: Nombres Y Apellidos | B5: Tipo de ID | C5: Numero de Id
A6: =+'1. Datos Aprendiz'!A8 -> Luiger Dalieth Ledezma Asprilla | B6: =+'1. Datos Aprendiz'!B8 -> T.I | C6: =+'1. Datos Aprendiz'!C8 -> 1105469704
A7: =+'1. Datos Aprendiz'!A9 -> Fayber Estyben Díaz Tierradentro | B7: =+'1. Datos Aprendiz'!B9 -> CC | C7: =+'1. Datos Aprendiz'!C9 -> 1075795667
A8: =+'1. Datos Aprendiz'!A10 | B8: =+'1. Datos Aprendiz'!B10 | C8: =+'1. Datos Aprendiz'!C10
A10: IDEAS DE NEGOCIO | B10: PROBLEMA, NECESIDAD U OPORTUNIDAD DETECTADO | I10: SOLUCIÓN IDENTIFICADA
A11: =+'3. Planteamiento Problema'!B4 -> Venta de componentes y repuestos de computadores | B11: =+'3. Planteamiento Problema'!C4 -> Uno de los problemas mas grandes y la oportunidad que tenemos con esta idea de negocio es que la gente no conoce de proveedores y sitios en donde la venta de estos repuestos sea un poco mas economica que pedir por internet y con la misma calidad. Pudiendo nosotros brindarles un asesoramiento con respecto a dichos componentes y la entrega del componente sera inmediata. | I11: =+'4. Opciones de Solucion'!C6 -> La solución a esta problemática es que con nosotros sabran un lugar de repuestos que se acomode a su presupuesto, podremos brindarle un asesoramiento de como se usa ese repuesto y le haremos entrega inmediata de ese producto segun lo que requiere el cliente.
A12: =+'3. Planteamiento Problema'!B5 -> Venta de repuesto de moto | B12: =+'3. Planteamiento Problema'!C5 -> La falta o ausencia de repuestos que se acomoden al presupuesto de una persona comun dificulta la compra de esos repuestos por eso esta idea de negocio buscan brindar productos originales y otros mas economicos para que el cliente pueda comprar el producto o repuesto de su preferencia. | I12: =+'4. Opciones de Solucion'!C7 -> La solución a esta problemática es que sabran de nosotros como un proveedor confiable en donde podran conseguir repuestos originales o de otra calidad.
A13: =+'3. Planteamiento Problema'!B6 -> Gimnasio orientado a fitness y crossfit | B13: =+'3. Planteamiento Problema'!C6 -> La falta o ausencia de gimnasios que no se logran acomodar al presupuesto de una persona comun ya que hay muchos establecimientos de gimnasio que tienen costos muy elevados y esto hace que se les dificulte adquirir de esos servicios y facilitarle a los clientes ofreciendole de otros servicios mas accesibles para ellos | I13: =+'4. Opciones de Solucion'!C8 -> La solución a esta problemática es que nosotros como un gimnasio brindaremos una membresia mensual y no haremos cobros de otros servicios que se pueda dificultar para ellos.
A16: MODELO DE NEGOCIO: | B16: =+'5. Toma de Decision'!B21 -> Tienda de electrónica: Venta de dispositivos electrónicos.
A17: IDEA DE NEGOCIOS ESCOGIDA: | B17: =+'5. Toma de Decision'!B22 -> Venta de componentes y repuestos de computadores
A18: SECTOR PRODUCTIVO: | B18: =+'6. ANALISIS PESTEL'!E3 -> SECTOR TERCEARIO
A19: ACTIVIDAD ECONOMICA: | B19: =+'6. ANALISIS PESTEL'!E4 -> Comercio electrónico y marketplaces
A20: NOMBRE IDEA DE NEGOCIOS: | B20: =+'8. Analisis Idea'!D5 -> CompuTech
A22: RESUMEN EJECUTIVO DE LOS CINCO (5) PRODUCTOS O SERVICIOS A VENDER EN EL EMPRENDIMIENTO | I22: Valor Agregado o Innovación propuesto
A23: PRODUCTO O SERVICIO 1 | B23: =+'8. Analisis Idea'!C10 -> Memoria RAM | I23: =+'8. Analisis Idea'!D9 -> Al haber una escases de RAM y un auomento excesivo haremos lo posible para vender la RAM a un precio menor comparado con la oferta que hay en el mercado.
A24: PRODUCTO O SERVICIO 2 | B24: =+'8. Analisis Idea'!C18 -> Disco SSD | I24: =+'8. Analisis Idea'!D17 -> Hay un creciente aumento en los precios de los discos haremos que los precios de los discos mantengan un precio menor con la oferta en el mercado.
A25: PRODUCTO O SERVICIO 3 | B25: =+'8. Analisis Idea'!C26 -> Disco M.2 | I25: =+'8. Analisis Idea'!D25 -> Hay un creciente aumento en los precios de los discos haremos que los precios de los discos mantengan un precio menor con la oferta en el mercado.
A26: PRODUCTO O SERVICIO 4 | B26: =+'8. Analisis Idea'!C34 -> Memorias USB: | I26: =+'8. Analisis Idea'!D33 -> Con el proximo aumento de las memorias USB haremos lo posible por mantener el precio o dar ofertas con respecto a ellas.
A27: PRODUCTO O SERVICIO 5 | B27: =+'8. Analisis Idea'!C42 -> Tarjeta grafica | I27: =+'8. Analisis Idea'!D41 -> Con las tarjetas graficas haremos que las personas que los compren reciban un certificado para su garantia por cierto tiempo y trataremos de dar precios competitivos
A29: =+'8. Analisis Idea'!F8 -> PRINCIPALES COMPETIDORES DIRECTOS (¿Quiénes son las empresas que competirán en el mercado con su negocio?, nombre 3)
A30: =+'8. Analisis Idea'!F9 -> Los posibles competidores podrian ser los negocios que se situan en la zona de comuneros como: Alphanet, Iphone store, TuConsultorTI.
A32: PROVEEDORES MATERIAS PRIMAS E INSUMOS
A33: =+'8. Analisis Idea'!G9 -> Los provedores que contariamos para la obtecion de repuestos serian: Kingston, Fury, ADATA, Samsung, MSI y Corsair
A35: =+'8. Analisis Idea'!H8 -> ESTRATEGIAS DE COMUNICACIÓN Y PROMOCIÓN (Redes Sociales, marketing digital)
A36: =+'8. Analisis Idea'!H9 -> Usar redes sociales estrategicas utilizando tiktok,instagram y facebook para utiilizar los reels y generar videos de un impacto inmediato diciendo las promociones que tengamos. Usar de whatsapp como un medio de comunicacion directa. Usando plataformas de mercado digital como Facebook Marketplace y MercadoLibre para publicar repuestos para que hagan compra de ello.
