Workbook

Sheet DATAE
A2: CRITERIOS DE SEGMENTACION DE MERCADOS
A4: SEGMENTACION DEMOGRÁFICA
A5: Género | B5: Rango de edad | C5: Nivel de Ingresos | D5: Nivel Educación | E5: Estado Civil | F5: Estrato Social | G5: ¿Familia? | H5: Oficio
A6: MASCULINO | B6: Entre 18 a 25 años | C6: Bajo (Hasta 1 SMMLV) | D6: Primaria | E6: Soltero(a) | F6: Bajo (Estratos 1 y 2) | G6: Con Hijos | H6: Independiente
A7: FEMENINO | B7: Entre 26 a 35 años | C7: Medio (entre 2 y 3 SMMLV) | D7: Bachillerato | E7: Casado(a) | F7: Medio (Estratos 3 y 4) | G7: Sin Hijos | H7: Ama de casa - Madre cabeza de hogar
A8: DIVERSO | B8: Entre 36 a 45 años | C8: Alto (mas de 3 SMMLV) | D8: Técnico o Técnologo | E8: Unión Libre | F8: Alto (Estratos 5 y 6) | H8: Contratista
B9: Entre 46 a 55 años | D9: Universitario | E9: Separado(a) | H9: Empleado
B10: Entre 56 a 65 años | H10: Empresario
B11: Entre 66 a 75 años | H11: Trabajador Informal
B12: Entre 76 a 86 años
B13: Más de 86 años
A15: --
A16: SEGMENTACION PSICOGRÁFICA
A17: Estilo de Vida 1 | B17: Estilo de Vida 2 | C17: Estilo de Vida 3 | D17: Personalidad | E17: Pensamientos o costumbres
A18: Lujoso - Ostentoso | B18: Se preocupa por su salud | C18: Activo y Deportivo | D18: Introvertid@ | E18: Conservador@ tradicionalista
A19: Austero - Sencillo | B19: No se preocupa por su salud | C19: Le gusta la tecnologýa y estar conectado | D19: Extrovertid@ | E19: Descomplicad@ no le teme a probar algo nuevo
C20: Le gusta lo ecológico y sostenible ambientalmente
C21: Le gusta lo gourmet y gastronómico
C22: Le gusta la cultura y tradiciones
C23: Su centro es su Familia y Hogar
C24: Es sedentario, no tiene una vida activa
C25: Le gusta la Moda y Estilo
C26: Le gusta las aventurero y los Viajes
A29: SEGMENTACION COMPORTAMENTAL
A30: Proceso de Compra | B30: Frecuencia de Compra | C30: ¿Qué busca lograr?
A31: Realiza compra basados en la razón y reflexión (Precio, Calidad) | B31: Diaria | C31: Satisfacer necesidades esenciales
A32: Realiza compra por impulso sin distingo de precio o marca | B32: Semanal | C32: Busca soluciones a problemas específicos
A33: Realiza compra por lealtad a una marca | B33: Quincenal | C33: Busca comprar Productos o servicios que le hagan la vida más fácil o ahorren tiempo.
B34: Bimensual | C34: Busca obtener la mejor calidad-precio del mercado
B35: trimestral | C35: Busca comprar productos o servicios que se alinean con su estilo de vida y valores
B36: Semestral | C36: Busca lograr prestigio y estatus
B37: Anual | C37: Busca satisfacer impulsos emocionales en la compra (Comprar un regalo)
C38: Busca mantenerse a la moda o seguir las últimas tendencias tecnológicas.
C39: Busca experiencias gratificantes, como viajes o eventos
C40: Busca comprar por preferencia por marcas que ya conoce y en las que confía
A43: SEGMENTACION GEOGRÁFICA
A44: Pais | B44: Departamento | C44: Ciudad | D44: Sector | E44: Barrio
A45: Colombia | B45: Huila | C45: Aipe | D45: Norte
C46: Algeciras | D46: Sur
C47: Baraya | D47: Oriente
...

Sheet Instrucciones
A1: INSTRUCCIONES DEL TALLER
A3: 1. Lea atentamente el GLOSARIO DE TERMINOS para realizar esta evidencia y comprender la temática de la actividad de aprendizaje propuesta.
A4: 2. Para el taller propuesto usted realizará las siguientes acciones:
B6: a. | C6: Siga atentamente las indicaciones del instructor. Lea el glosario de términos y la hoja " Tipos de Segmentación de mercados"
B7: b. | C7: Describa el nombre de los productos o servicios que estableció en la evidencia taller Ideación, Caracterización y Valoración de la Idea de Negocio
B8: c. | C8: Teniendo en cuenta el taller Ideación, Caracterización y Valoración de la Idea de Negocio, y a los productos o servicios que especificó en esa evidencia, identifique la mayor cantidad de rasgos de las Tarjetas Persona que aparecen en el archivo anexo en plataforma, es un archivo en PDF. Realice TODAS las tarjetas persona, analice si estas personas podrían ser sus clientes.
B9: d. | C9: Especifique en el Lienzo Generación de Propuesta de Valor, cual es la propuesta que sus productos o servicios cumplirán a sus clientes

Sheet Datos Aprendices
A1: =+CONCATENATE(A13,A23,B13,A23,C13,A23,A14,A23,B14,A23,C14,A23,A15,A23,B15,A23,C15,A23,C17,A23,C18,A23,E18,A23,A5) -> Luiger Dalieth Ledezma Asprilla -- TI -- 1105469704 -- Fayber Estyben Díaz Tierradentro -- CC -- 1075795667 -- -- -- -- Analisis y desarollo de software -- 3413988 -- TARDE -- Taller ¿Quién es esta persona? Segmentación de Mercados Versión 2.0 2025 Desarrollado por Instructor Emprendimiento para el SENA como instrumento de apoyo a la formación.
A3: Diligencie únicamente las celdas en color AMARILLO
F4: --
A5: Taller ¿Quién es esta persona? Segmentación de Mercados Versión 2.0 2025 Desarrollado por Instructor Emprendimiento para el SENA como instrumento de apoyo a la formación.
K6: --
A7: Instrucciones:
A9: 1. Solo diligencie las celdas en color Amarillo según el campo solicitado
A10: 2. Ingrese los valores permitidos en cada celda, según corresponda a su análisis de cada perfil de cliente
A12: Nombres Y Apellidos | B12: Tipo de ID | C12: Numero de Id | D12: Teléfono de contacto | E12: Correo Electrónico
A13: Luiger Dalieth Ledezma Asprilla | B13: TI | C13: 1105469704 | D13: 3142703700 | E13: luugerdalieth@gmail.com
A14: Fayber Estyben Díaz Tierradentro | B14: CC | C14: 1075795667 | D14: 3234689690 | E14: diazfayber27@gmail.com
A17: Formación Titulada: | C17: Analisis y desarollo de software
A18: Número de Ficha: | C18: 3413988 | D18: Jornada | E18: TARDE
A20: Recuerde: No se recibirá este taller si no están detallados los datos de quienes participan en la presente actividad
A23: --
A29: CC
A30: TI
A31: PTP
A32: CE
A34: MAÑANA
A35: TARDE
A36: NOCHE
A37: MIXTA

Sheet Glosario
A1: GLOSARIO DE TERMINOS DE ESTE TALLER
A4: Producto: | B4: Un producto es todo aquello que está a disposición, es decir, en el mercado, para que cualquier usuario lo adquiera con la finalidad de satisfacer una necesidad un deseo. Son Tangibles, es decir se pueden tocar, ver, degustar.
A6: Servicio: | B6: Prestación que satisface alguna necesidad humana y que no consiste en la producción de bienes materiales. Un servicio es una prestación, un activo de naturaleza económica pero que no tiene presencia física propia (es intangible), a diferencia de los productos que si la tienen.
A8: Cliente: | B8: Un cliente es una persona o entidad que compra bienes o servicios de una empresa. En otras palabras, es quien compra lo que una empresa ofrece: a. Clientes individuales: Personas que compran para uso personal o familiar. b. Clientes empresariales: Empresas que compran productos o servicios para su uso interno o para revenderlos. c. Clientes gubernamentales: Entidades gubernamentales que adquieren bienes o servicios para satisfacer necesidades públicas. d. Clientes recurrentes: Aquellos que realizan compras de forma regular. e. Clientes potenciales: Personas o empresas que podrían convertirse en clientes en el futuro
A10: Consumidor: | B10: Un consumidor es una persona que consume bienes o servicios para satisfacer sus necesidades o deseos personales. Es la persona final que utiliza un producto o servicio. Busca: a. Necesidades y deseos: El consumidor busca satisfacer necesidades básicas (como alimentación, vivienda) o deseos (como entretenimiento, estatus). b. Comportamiento de compra: El consumidor sigue un proceso de compra que incluye la búsqueda de información, la evaluación de opciones y la decisión de compra. c. Influencias: Las decisiones de compra del consumidor están influenciadas por factores internos (como la personalidad, la edad, el estilo de vida) y externos (como la cultura, la familia, los amigos, la publicidad). d. Segmentación: Los consumidores se pueden segmentar en grupos más pequeños basados en características comunes (demográficas, psicográficas, geográficas, conductuales) para adaptar las estrategias de marketing. e. Valor: El consumidor busca obtener el mayor valor por su dinero, considerando factores como la calidad, el precio, la marca y la experiencia de compra.
A12: Segmentación de Mercados: | B12: La segmentación de mercados es una estrategia de marketing que consiste en dividir un mercado grande y heterogéneo en grupos más pequeños de consumidores que comparten características similares. Estos grupos, llamados segmentos, tienen necesidades, deseos y comportamientos de compra similares, lo que permite a las empresas adaptar sus productos, servicios y mensajes de marketing de manera más efectiva.
A14: Tareas o trabajos del Cliente: | B14: Son las actividades que un cliente intenta resolver en su vida diaria o laboral. Estas tareas pueden ser desde las más simples, como encontrar un producto específico, hasta las más complejas, como tomar una decisión de compra importante. Comprender las tareas que los clientes intentan realizar es fundamental para las empresas, ya que les permite: a. Desarrollar productos y servicios más relevantes: Al conocer las tareas específicas de los clientes, las empresas pueden diseñar soluciones que se ajusten perfectamente a sus necesidades. b. Crear mensajes de marketing más efectivos: Los mensajes publicitarios pueden ser más persuasivos si se enfocan en cómo un producto o servicio puede ayudar al cliente a completar una tarea. c. Mejorar la experiencia del cliente: Al entender los puntos de fricción en el proceso de compra, las empresas pueden optimizar la experiencia del cliente y reducir la tasa de abandono.
A16: Alegrias del Cliente: | B16: Tambien llamados Generadores de beneficios. Las alegrías del cliente son los resultados y beneficios que un cliente busca y espera obtener al adquirir un producto o servicio. Van más allá de la simple satisfacción de una necesidad básica y se refieren a los deseos, aspiraciones y emociones positivas que un cliente desea experimentar. Tipos de Alegrías del Cliente: a. Alegrías Necesarias: Son aquellas sin las cuales el producto o servicio no funcionaría. Por ejemplo, en un restaurante, una comida sabrosa es una alegría necesaria. b. Alegrías Esperadas: Son las que los clientes esperan recibir como estándar. Por ejemplo, un servicio al cliente amable y eficiente. c. Alegrías Deseadas: Son las que van más allá de lo esperado y que los clientes desearían tener. Por ejemplo, una experiencia gastronómica única y memorable. d. Alegrías Sorpresa: Son aquellas que los clientes no esperan y que les causan una gran satisfacción. Por ejemplo, un regalo inesperado con la compra.
A18: Tristezas del Cliente (generadores de angustias o dolores): | B18: Las tristezas o frustraciones del cliente son las emociones negativas que experimenta un consumidor al interactuar con una marca, producto o servicio. Estas emociones pueden surgir debido a una variedad de factores, desde una mala experiencia de compra hasta un producto que no cumple con las expectativa. Causas comunes de las tristezas del cliente: a. Producto o servicio defectuoso: Cuando un producto no funciona como se esperaba o un servicio no cumple con los estándares de calidad. b. Mala atención al cliente: Un servicio al cliente lento, poco amable o poco profesional puede generar frustración. c. Experiencia de compra negativa: Dificultades para encontrar un producto, procesos de compra complicados o tiempos de espera excesivos. d. Comunicación deficiente: Información errónea, falta de transparencia o respuestas evasivas. e. Experiencias negativas en redes sociales: Comentarios negativos de otros clientes o respuestas inadecuadas de la marca.
A20: Propuesta de Valor: | B20: Un lienzo de propuesta de valor es una herramienta visual que ayuda a alinear las necesidades de sus clientes con los beneficios que ofrecen los productos o servicios. Es un mapa que guía para crear una oferta que realmente resuene con su público objetivo.

Sheet 1 . Productos o Servicios
A1: =+'Datos Aprendices'!A1 -> Luiger Dalieth Ledezma Asprilla -- TI -- 1105469704 -- Fayber Estyben Díaz Tierradentro -- CC -- 1075795667 -- -- -- -- Analisis y desarollo de software -- 3413988 -- TARDE -- Taller ¿Quién es esta persona? Segmentación de Mercados Versión 2.0 2025 Desarrollado por Instructor Emprendimiento para el SENA como instrumento de apoyo a la formación.
A3: Por favor en los espacios en amarillo describa ESPECIFICAMENTE los produtos o servicios a vender en el emprendimiento. Tenga en cuenta que por cada renglón es UN produto o servicio. No generalice en un rtenglón varios, es decir proponga cada uno en SINGULAR y no en plural
A5: Ejemplo 1: Diga para un negocio de pandería, describa un producto "MOJICON DULCE" y no "panes". Recuerde que debe ser especifico
A6: Ejemplo 2: Diga para un negocio de servicios de mantenimiento, describa un servicio "cambio de aceite vehiculo" y no "mantenimientos". Recuerde que debe ser especifico
A9: ¿Qué Productos o Servicios ESPECIFICOS va a vender en su emprendimiento?
A10: 1 Servicio tecnico
A11: 2 Disco SSD
A12: 3 Memoria RAM
A13: 4 Tarjeta grafica
A14: 5 Ensamble y personalizacion

Sheet Tipos de Segmentación Mercados
A1: =+'1 . Productos o Servicios'!A1 -> Luiger Dalieth Ledezma Asprilla -- TI -- 1105469704 -- Fayber Estyben Díaz Tierradentro -- CC -- 1075795667 -- -- -- -- Analisis y desarollo de software -- 3413988 -- TARDE -- Taller ¿Quién es esta persona? Segmentación de Mercados Versión 2.0 2025 Desarrollado por Instructor Emprendimiento para el SENA como instrumento de apoyo a la formación.
A3: Tipos de Segmentación de Mercados
A5: 1. Segmentación Demográfica: | B5: La segmentación demográfica divide el mercado basándose en características de la población que son fáciles de medir. Es uno de los tipos de segmentación más comunes y sencillos de aplicar, como la edad, género, ingresos, ocupación, nivel educativo, estado civil, tamaño de la familia.
B6: Ejemplo: Una marca de pañales se dirige a padres con bebés y niños pequeños (edad, estado familiar). Una empresa de autos de lujo se enfoca en personas con altos ingresos (ingresos).
A8: 2. Segmentación Geográfica: | B8: La segmentación geográfica divide el mercado dependiendo la zona geográfica donde viva el cliente. Las necesidades y preferencias de los clientes pueden variar según su ubicación.
B9: Ejemplo: Una empresa de ropa de invierno vende abrigos y bufandas en regiones con climas fríos, mientras que en zonas tropicales promociona ropa ligera y de verano
A11: 3. Segmentación Psicográfica | B11: La segmentación psicográfica divide el mercado basándose en características psicológicas y de estilo de vida de los clientes. Va más allá de lo obvio para entender el "porqué" detrás de sus decisiones, como Personalidad, estilo de vida (actividades, intereses, opiniones), valores, creencias, actitudes.
B12: Ejemplo: Una marca de productos ecológicos se dirige a consumidores que valoran la sostenibilidad, tienen un estilo de vida consciente con el medio ambiente y buscan productos que reflejen sus principios éticos
A14: 4. Segmentación Conductual (o de Comportamiento) | B14: La segmentación conductual divide el mercado basándose en los comportamientos observables de los clientes en relación con el producto o servicio. Se centra en lo que los clientes hacen, cómo interactúan con la marca y sus patrones de compra, como frecuencia de compra, volumen de compra, beneficios buscados, ocasión de compra o uso, nivel de lealtad a la marca
B15: Ejemplo: Una plataforma de streaming de música segmenta a sus usuarios según la frecuencia con la que escuchan música, los géneros que prefieren

Sheet Tarjeta Persona 1
A1: =+'1 . Productos o Servicios'!A1 -> Luiger Dalieth Ledezma Asprilla -- TI -- 1105469704 -- Fayber Estyben Díaz Tierradentro -- CC -- 1075795667 -- -- -- -- Analisis y desarollo de software -- 3413988 -- TARDE -- Taller ¿Quién es esta persona? Segmentación de Mercados Versión 2.0 2025 Desarrollado por Instructor Emprendimiento para el SENA como instrumento de apoyo a la formación.
A3: CARACTERIZACION CLIENTE OBJETIVO "QUIEN ES ESTA PERSONA"
A5: SEGMENTACION DEMOGRÁFICA ¿Quién es? | D5: SEGMENTACION GEOGRÁFICA ¿Dónde Vive?
A6: Género | B6: MASCULINO | D6: Pais | E6: Colombia
A7: Rango de Edad | B7: Entre 36 a 45 años | D7: Departamento | E7: Huila
A8: Nivel de Ingresos | B8: Medio (entre 2 y 3 SMMLV) | D8: Municipio | E8: Neiva
A9: Nivel Educación | B9: Universitario | D9: Sector | E9: Occidente
A10: Estado Civil | B10: Casado(a) | D10: Zona | E10: Urbana
A11: Familia | B11: Con Hijos
A12: Estrato Social | B12: Medio (Estratos 3 y 4)
A13: Oficio | B13: Empleado
A16: Estilo de vida | B16: Lujoso - Ostentoso | G16: SEGMENTACION PSICOGRÁFICA ¿Quiénes son como individuos, como actúan en su diario vivir?
B17: Se preocupa por su salud
B18: Es sedentario, no tiene una vida activa
B19: Su centro es su Familia y Hogar
A21: Personalidad | D21: Introvertid@
A22: Pensamientos o costumbres | D22: Conservador@ tradicionalista
D24: SEGMENTACION COMPORTAMENTAL ¿Cómo compra el cliente? ¿Por qué compra el cliente su producto o servicio?
C25: Realiza compra basados en la razón y reflexión (Precio, Calidad) | G25: ¿Cual es el Proceso de Compra de su cliente?
F26: Semestral | G26: ¿Cuál es la Frecuencia de Compra de su cliente?
A27: Busca comprar Productos o servicios que le hagan la vida más fácil o ahorren tiempo. | G27: ¿Qué busca lograr cuando compra su cliente?
A29: Para los Productos o Servicios que usted venderá:
A30: =+'1 . Productos o Servicios'!A10 -> 1 Servicio tecnico | E30: ¿Su cliente compraría este producto? | H30: SI
A31: =+'1 . Productos o Servicios'!A11 -> 2 Disco SSD | E31: ¿Su cliente compraría este producto? | H31: SI
A32: =+'1 . Productos o Servicios'!A12 -> 3 Memoria RAM | E32: ¿Su cliente compraría este producto? | H32: NO
A33: =+'1 . Productos o Servicios'!A13 -> 4 Tarjeta grafica | E33: ¿Su cliente compraría este producto? | H33: NO
A34: =+'1 . Productos o Servicios'!A14 -> 5 Ensamble y personalizacion | E34: ¿Su cliente compraría este producto? | H34: SI
A36: Perfil del Cliente Resumen
A37: =+CONCATENATE(DATAE!A87,DATAE!A91,'Tarjeta Persona 1'!B6,DATAE!A91,'Tarjeta Persona 1'!B7,DATAE!A94,'Tarjeta Persona 1'!B8,DATAE!A91,'Tarjeta Persona 1'!B9,DATAE!A91,'Tarjeta Persona 1'!B10,DATAE!A91,'Tarjeta Persona 1'!B11,DATAE!A93,'Tarjeta Persona 1'!B12,DATAE!A91,'Tarjeta Persona 1'!B13,DATAE!A91,'Tarjeta Persona 1'!A16,DATAE!A91,'Tarjeta Persona 1'!B16,DATAE!A91,'Tarjeta Persona 1'!B17,DATAE!A91,'Tarjeta Persona 1'!B18,DATAE!A91,'Tarjeta Persona 1'!B19,DATAE!A91,'Tarjeta Persona 1'!A21,DATAE!A91,'Tarjeta Persona 1'!D21,DATAE!A91,'Tarjeta Persona 1'!A22,DATAE!A91,'Tarjeta Persona 1'!D22,DATAE!A91,C25,DATAE!A91,DATAE!A92,'Tarjeta Persona 1'!F26,DATAE!A91,'Tarjeta Persona 1'!A27,DATAE!A89,'Tarjeta Persona 1'!D7,DATAE!A91,'Tarjeta Persona 1'!E7,DATAE!A91,'Tarjeta Persona 1'!D8,DATAE!A91,'Tarjeta Persona 1'!E8,DATAE!A91,'Tarjeta Persona 1'!D9,DATAE!A91,'Tarjeta Persona 1'!E9,D10,DATAE!A15,'Tarjeta Persona 1'!E10) -> El perfil de esta persona es MASCULINO Entre 36 a 45 años Con ingresos Medio (entre 2 y 3 SMMLV) Universitario Casado(a) Con Hijos Vive en Estrato Medio (Estratos 3 y 4) Empleado Estilo de vida Lujoso - Ostentoso Se preocupa por su salud Es sedentario, no tiene una vida activa Su centro es su Familia y Hogar Personalidad Introvertid@ Pensamientos o costumbres Conservador@ tradicionalista Realiza compra basados en la razón y reflexión (Precio, Calidad) Compra con frecuencia Semestral Busca comprar Productos o servicios que le hagan la vida más fácil o ahorren tiempo. El cliente vive en Departamento Huila Municipio Neiva Sector Occidente Zona -- Urbana
A39: Justifique por que cree usted que esta persona puede ser su cliente, que problema o necesidad le esta resolviendo, (3 lineas de texto), lea bien los conceptos de tipos de segmentación.
A40: Esta persona puede ser cliente de mi negocio para adquirir equipos de computo o componentes para mejorar los que ya tiene. Solucionar problemas por equipos lentos, licencias, daños en componentes ademas de soporte para una orientacion de que puede hacer con sus equipos de computo o ayudar con equipos que puedan tener en su casa y puedan colaborarle a su familia o amigos.

Sheet Tarjeta Persona 2
A1: =+'1 . Productos o Servicios'!A1 -> Luiger Dalieth Ledezma Asprilla -- TI -- 1105469704 -- Fayber Estyben Díaz Tierradentro -- CC -- 1075795667 -- -- -- -- Analisis y desarollo de software -- 3413988 -- TARDE -- Taller ¿Quién es esta persona? Segmentación de Mercados Versión 2.0 2025 Desarrollado por Instructor Emprendimiento para el SENA como instrumento de apoyo a la formación.
A3: CARACTERIZACION CLIENTE OBJETIVO "QUIEN ES ESTA PERSONA"
A5: SEGMENTACION DEMOGRÁFICA ¿Quién es? | D5: SEGMENTACION GEOGRÁFICA ¿Dónde Vive?
A6: Género | B6: FEMENINO | D6: Pais | E6: Colombia
A7: Rango de Edad | B7: Entre 18 a 25 años | D7: Departamento | E7: Huila
A8: Nivel de Ingresos | B8: Bajo (Hasta 1 SMMLV) | D8: Municipio | E8: Neiva
A9: Nivel Educación | B9: Bachillerato | D9: Sector | E9: Norte
A10: Estado Civil | B10: Soltero(a) | D10: Zona | E10: Urbana
A11: Familia | B11: Sin Hijos
A12: Estrato Social | B12: Bajo (Estratos 1 y 2)
A13: Oficio | B13: Empleado
A16: Estilo de vida | B16: Austero - Sencillo | G16: SEGMENTACION PSICOGRÁFICA ¿Quiénes son como individuos, como actúan en su diario vivir?
B17: Se preocupa por su salud
B18: Le gusta lo gourmet y gastronómico
B19: Su centro es su Familia y Hogar
A21: Personalidad | D21: Extrovertid@
A22: Pensamientos o costumbres | D22: Descomplicad@ no le teme a probar algo nuevo
D24: SEGMENTACION COMPORTAMENTAL ¿Cómo compra el cliente? ¿Por qué compra el cliente su producto o servicio?
C25: Realiza compra basados en la razón y reflexión (Precio, Calidad) | G25: ¿Cual es el Proceso de Compra de su cliente?
F26: Semestral | G26: ¿Cuál es la Frecuencia de Compra de su cliente?
A27: Busca obtener la mejor calidad-precio del mercado | G27: ¿Qué busca lograr cuando compra su cliente?
A29: Para los Productos o Servicios que usted venderá:
A30: =+'1 . Productos o Servicios'!A10 -> 1 Servicio tecnico | E30: ¿Su cliente compraría este producto? | H30: SI
A31: =+'1 . Productos o Servicios'!A11 -> 2 Disco SSD | E31: ¿Su cliente compraría este producto? | H31: SI
A32: =+'1 . Productos o Servicios'!A12 -> 3 Memoria RAM | E32: ¿Su cliente compraría este producto? | H32: NO
A33: =+'1 . Productos o Servicios'!A13 -> 4 Tarjeta grafica | E33: ¿Su cliente compraría este producto? | H33: NO
A34: =+'1 . Productos o Servicios'!A14 -> 5 Ensamble y personalizacion | E34: ¿Su cliente compraría este producto? | H34: SI
A36: Perfil del Cliente Resumen
A37: =+CONCATENATE(DATAE!A87,DATAE!A91,'Tarjeta Persona 2'!B6,DATAE!A91,'Tarjeta Persona 2'!B7,DATAE!A94,'Tarjeta Persona 2'!B8,DATAE!A91,'Tarjeta Persona 2'!B9,DATAE!A91,'Tarjeta Persona 2'!B10,DATAE!A91,'Tarjeta Persona 2'!B11,DATAE!A93,'Tarjeta Persona 2'!B12,DATAE!A91,'Tarjeta Persona 2'!B13,DATAE!A91,'Tarjeta Persona 2'!A16,DATAE!A91,'Tarjeta Persona 2'!B16,DATAE!A91,'Tarjeta Persona 2'!B17,DATAE!A91,'Tarjeta Persona 2'!B18,DATAE!A91,'Tarjeta Persona 2'!B19,DATAE!A91,'Tarjeta Persona 2'!A21,DATAE!A91,'Tarjeta Persona 2'!D21,DATAE!A91,'Tarjeta Persona 2'!A22,DATAE!A91,'Tarjeta Persona 2'!D22,DATAE!A91,C25,DATAE!A91,DATAE!A92,'Tarjeta Persona 2'!F26,DATAE!A91,'Tarjeta Persona 2'!A27,DATAE!A89,'Tarjeta Persona 2'!D7,DATAE!A91,'Tarjeta Persona 2'!E7,DATAE!A91,'Tarjeta Persona 2'!D8,DATAE!A91,'Tarjeta Persona 2'!E8,DATAE!A91,'Tarjeta Persona 2'!D9,DATAE!A91,'Tarjeta Persona 2'!E9,D10,DATAE!A15,'Tarjeta Persona 2'!E10) -> El perfil de esta persona es FEMENINO Entre 18 a 25 años Con ingresos Bajo (Hasta 1 SMMLV) Bachillerato Soltero(a) Sin Hijos Vive en Estrato Bajo (Estratos 1 y 2) Empleado Estilo de vida Austero - Sencillo Se preocupa por su salud Le gusta lo gourmet y gastronómico Su centro es su Familia y Hogar Personalidad Extrovertid@ Pensamientos o costumbres Descomplicad@ no le teme a probar algo nuevo Realiza compra basados en la razón y reflexión (Precio, Calidad) Compra con frecuencia Semestral Busca obtener la mejor calidad-precio del mercado El cliente vive en Departamento Huila Municipio Neiva Sector Norte Zona -- Urbana
A39: Justifique por que cree usted que esta persona puede ser su cliente, que problema o necesidad le esta resolviendo, (3 lineas de texto), lea bien los conceptos de tipos de segmentación.
A40: Esta persona puede ser mi cliente porque puede adquierir algun computador de mesa o portatil para continuar sus estudios o para uso basico personal teniendo en cuenta sus ingresos, o si ya tiene un portatil y es muy basico o lento se le pueden dar unas mejores ajustadas a los ingresos de la persona.

Sheet Tarjeta Persona 3
A1: =+'1 . Productos o Servicios'!A1 -> Luiger Dalieth Ledezma Asprilla -- TI -- 1105469704 -- Fayber Estyben Díaz Tierradentro -- CC -- 1075795667 -- -- -- -- Analisis y desarollo de software -- 3413988 -- TARDE -- Taller ¿Quién es esta persona? Segmentación de Mercados Versión 2.0 2025 Desarrollado por Instructor Emprendimiento para el SENA como instrumento de apoyo a la formación.
A3: CARACTERIZACION CLIENTE OBJETIVO "QUIEN ES ESTA PERSONA"
A5: SEGMENTACION DEMOGRÁFICA ¿Quién es? | D5: SEGMENTACION GEOGRÁFICA ¿Dónde Vive?
A6: Género | B6: MASCULINO | D6: Pais | E6: Colombia
A7: Rango de Edad | B7: Entre 18 a 25 años | D7: Departamento | E7: Huila
A8: Nivel de Ingresos | B8: Medio (entre 2 y 3 SMMLV) | D8: Municipio | E8: Neiva
A9: Nivel Educación | B9: Técnico o Técnologo | D9: Sector | E9: Oriente
A10: Estado Civil | B10: Soltero(a) | D10: Zona | E10: Urbana
A11: Familia | B11: Sin Hijos
A12: Estrato Social | B12: Medio (Estratos 3 y 4)
A13: Oficio | B13: Independiente
A16: Estilo de vida | B16: Lujoso - Ostentoso | G16: SEGMENTACION PSICOGRÁFICA ¿Quiénes son como individuos, como actúan en su diario vivir?
B17: Se preocupa por su salud
B18: Le gusta la tecnologýa y estar conectado
B19: Le gusta la Moda y Estilo
A21: Personalidad | D21: Extrovertid@
A22: Pensamientos o costumbres | D22: Descomplicad@ no le teme a probar algo nuevo
D24: SEGMENTACION COMPORTAMENTAL ¿Cómo compra el cliente? ¿Por qué compra el cliente su producto o servicio?
C25: Realiza compra basados en la razón y reflexión (Precio, Calidad) | G25: ¿Cual es el Proceso de Compra de su cliente?
F26: Semestral | G26: ¿Cuál es la Frecuencia de Compra de su cliente?
A27: Busca comprar Productos o servicios que le hagan la vida más fácil o ahorren tiempo. | G27: ¿Qué busca lograr cuando compra su cliente?
A29: Para los Productos o Servicios que usted venderá:
A30: =+'1 . Productos o Servicios'!A10 -> 1 Servicio tecnico | E30: ¿Su cliente compraría este producto? | H30: SI
A31: =+'1 . Productos o Servicios'!A11 -> 2 Disco SSD | E31: ¿Su cliente compraría este producto? | H31: SI
A32: =+'1 . Productos o Servicios'!A12 -> 3 Memoria RAM | E32: ¿Su cliente compraría este producto? | H32: SI
A33: =+'1 . Productos o Servicios'!A13 -> 4 Tarjeta grafica | E33: ¿Su cliente compraría este producto? | H33: SI
A34: =+'1 . Productos o Servicios'!A14 -> 5 Ensamble y personalizacion | E34: ¿Su cliente compraría este producto? | H34: SI
A36: Perfil del Cliente Resumen
A37: =+CONCATENATE(DATAE!A87,DATAE!A91,'Tarjeta Persona 3'!B6,DATAE!A91,'Tarjeta Persona 3'!B7,DATAE!A94,'Tarjeta Persona 3'!B8,DATAE!A91,'Tarjeta Persona 3'!B9,DATAE!A91,'Tarjeta Persona 3'!B10,DATAE!A91,'Tarjeta Persona 3'!B11,DATAE!A93,'Tarjeta Persona 3'!B12,DATAE!A91,'Tarjeta Persona 3'!B13,DATAE!A91,'Tarjeta Persona 3'!A16,DATAE!A91,'Tarjeta Persona 3'!B16,DATAE!A91,'Tarjeta Persona 3'!B17,DATAE!A91,'Tarjeta Persona 3'!B18,DATAE!A91,'Tarjeta Persona 3'!B19,DATAE!A91,'Tarjeta Persona 3'!A21,DATAE!A91,'Tarjeta Persona 3'!D21,DATAE!A91,'Tarjeta Persona 3'!A22,DATAE!A91,'Tarjeta Persona 3'!D22,DATAE!A91,C25,DATAE!A91,DATAE!A92,'Tarjeta Persona 3'!F26,DATAE!A91,'Tarjeta Persona 3'!A27,DATAE!A89,'Tarjeta Persona 3'!D7,DATAE!A91,'Tarjeta Persona 3'!E7,DATAE!A91,'Tarjeta Persona 3'!D8,DATAE!A91,'Tarjeta Persona 3'!E8,DATAE!A91,'Tarjeta Persona 3'!D9,DATAE!A91,'Tarjeta Persona 3'!E9,D10,DATAE!A15,'Tarjeta Persona 3'!E10) -> El perfil de esta persona es MASCULINO Entre 18 a 25 años Con ingresos Medio (entre 2 y 3 SMMLV) Técnico o Técnologo Soltero(a) Sin Hijos Vive en Estrato Medio (Estratos 3 y 4) Independiente Estilo de vida Lujoso - Ostentoso Se preocupa por su salud Le gusta la tecnologýa y estar conectado Le gusta la Moda y Estilo Personalidad Extrovertid@ Pensamientos o costumbres Descomplicad@ no le teme a probar algo nuevo Realiza compra basados en la razón y reflexión (Precio, Calidad) Compra con frecuencia Semestral Busca comprar Productos o servicios que le hagan la vida más fácil o ahorren tiempo. El cliente vive en Departamento Huila Municipio Neiva Sector Oriente Zona -- Urbana
A39: Justifique por que cree usted que esta persona puede ser su cliente, que problema o necesidad le esta resolviendo, (3 lineas de texto), lea bien los conceptos de tipos de segmentación.
A40: Mi cliente potencial necesita reparar o mejorar sus dispositivos tecnológicos sin tener que comprar equipos nuevos constantemente. Mi negocio le proporciona repuestos, mantenimiento y actualizaciones que prolongan la vida útil de sus computadores. Así puede ahorrar dinero y obtener un mejor rendimiento. Y al ser de ese estilo de vida siendo tan joven posiblemente en el transcurso puede ir mejorando los componentes y nosotros podriamos ser su medio para ello.

Sheet Tarjeta Persona 4
A1: =+'1 . Productos o Servicios'!A1 -> Luiger Dalieth Ledezma Asprilla -- TI -- 1105469704 -- Fayber Estyben Díaz Tierradentro -- CC -- 1075795667 -- -- -- -- Analisis y desarollo de software -- 3413988 -- TARDE -- Taller ¿Quién es esta persona? Segmentación de Mercados Versión 2.0 2025 Desarrollado por Instructor Emprendimiento para el SENA como instrumento de apoyo a la formación.
A3: CARACTERIZACION CLIENTE OBJETIVO "QUIEN ES ESTA PERSONA"
A5: SEGMENTACION DEMOGRÁFICA ¿Quién es? | D5: SEGMENTACION GEOGRÁFICA ¿Dónde Vive?
A6: Género | B6: FEMENINO | D6: Pais | E6: Colombia
A7: Rango de Edad | B7: Entre 18 a 25 años | D7: Departamento | E7: Huila
A8: Nivel de Ingresos | B8: Medio (entre 2 y 3 SMMLV) | D8: Municipio | E8: Neiva
A9: Nivel Educación | B9: Universitario | D9: Sector | E9: Sur
A10: Estado Civil | B10: Soltero(a) | D10: Zona | E10: Urbana
A11: Familia | B11: Sin Hijos
A12: Estrato Social | B12: Medio (Estratos 3 y 4)
A13: Oficio | B13: Independiente
A16: Estilo de vida | B16: Lujoso - Ostentoso | G16: SEGMENTACION PSICOGRÁFICA ¿Quiénes son como individuos, como actúan en su diario vivir?
B17: Se preocupa por su salud
B18: Le gusta la tecnologýa y estar conectado
B19: Le gusta la Moda y Estilo
A21: Personalidad | D21: Introvertid@
A22: Pensamientos o costumbres | D22: Descomplicad@ no le teme a probar algo nuevo
D24: SEGMENTACION COMPORTAMENTAL ¿Cómo compra el cliente? ¿Por qué compra el cliente su producto o servicio?
C25: Realiza compra basados en la razón y reflexión (Precio, Calidad) | G25: ¿Cual es el Proceso de Compra de su cliente?
F26: Semestral | G26: ¿Cuál es la Frecuencia de Compra de su cliente?
A27: Busca mantenerse a la moda o seguir las últimas tendencias tecnológicas. | G27: ¿Qué busca lograr cuando compra su cliente?
A29: Para los Productos o Servicios que usted venderá:
A30: =+'1 . Productos o Servicios'!A10 -> 1 Servicio tecnico | E30: ¿Su cliente compraría este producto? | H30: SI
A31: =+'1 . Productos o Servicios'!A11 -> 2 Disco SSD | E31: ¿Su cliente compraría este producto? | H31: SI
A32: =+'1 . Productos o Servicios'!A12 -> 3 Memoria RAM | E32: ¿Su cliente compraría este producto? | H32: SI
A33: =+'1 . Productos o Servicios'!A13 -> 4 Tarjeta grafica | E33: ¿Su cliente compraría este producto? | H33: SI
A34: =+'1 . Productos o Servicios'!A14 -> 5 Ensamble y personalizacion | E34: ¿Su cliente compraría este producto? | H34: SI
A36: Perfil del Cliente Resumen
A37: =+CONCATENATE(DATAE!A87,DATAE!A91,'Tarjeta Persona 4'!B6,DATAE!A91,'Tarjeta Persona 4'!B7,DATAE!A94,'Tarjeta Persona 4'!B8,DATAE!A91,'Tarjeta Persona 4'!B9,DATAE!A91,'Tarjeta Persona 4'!B10,DATAE!A91,'Tarjeta Persona 4'!B11,DATAE!A93,'Tarjeta Persona 4'!B12,DATAE!A91,'Tarjeta Persona 4'!B13,DATAE!A91,'Tarjeta Persona 4'!A16,DATAE!A91,'Tarjeta Persona 4'!B16,DATAE!A91,'Tarjeta Persona 4'!B17,DATAE!A91,'Tarjeta Persona 4'!B18,DATAE!A91,'Tarjeta Persona 4'!B19,DATAE!A91,'Tarjeta Persona 4'!A21,DATAE!A91,'Tarjeta Persona 4'!D21,DATAE!A91,'Tarjeta Persona 4'!A22,DATAE!A91,'Tarjeta Persona 4'!D22,DATAE!A91,C25,DATAE!A91,DATAE!A92,'Tarjeta Persona 4'!F26,DATAE!A91,'Tarjeta Persona 4'!A27,DATAE!A89,'Tarjeta Persona 4'!D7,DATAE!A91,'Tarjeta Persona 4'!E7,DATAE!A91,'Tarjeta Persona 4'!D8,DATAE!A91,'Tarjeta Persona 4'!E8,DATAE!A91,'Tarjeta Persona 4'!D9,DATAE!A91,'Tarjeta Persona 4'!E9,D10,DATAE!A15,'Tarjeta Persona 4'!E10) -> El perfil de esta persona es FEMENINO Entre 18 a 25 años Con ingresos Medio (entre 2 y 3 SMMLV) Universitario Soltero(a) Sin Hijos Vive en Estrato Medio (Estratos 3 y 4) Independiente Estilo de vida Lujoso - Ostentoso Se preocupa por su salud Le gusta la tecnologýa y estar conectado Le gusta la Moda y Estilo Personalidad Introvertid@ Pensamientos o costumbres Descomplicad@ no le teme a probar algo nuevo Realiza compra basados en la razón y reflexión (Precio, Calidad) Compra con frecuencia Semestral Busca mantenerse a la moda o seguir las últimas tendencias tecnológicas. El cliente vive en Departamento Huila Municipio Neiva Sector Sur Zona -- Urbana
A39: Justifique por que cree usted que esta persona puede ser su cliente, que problema o necesidad le esta resolviendo, (3 lineas de texto), lea bien los conceptos de tipos de segmentación.
A40: Esta persona seria mi cliente ya que es una persona que le gusta estarse actualizando y le gusta comprar productos de calidad y aun precio bueno y accesible. Aparte tiene la posibilidad de comprar cosas lujosas y de una calidad premium.

Sheet Lienzo Propuesta de Valor
A1: =+'1 . Productos o Servicios'!A1 -> Luiger Dalieth Ledezma Asprilla -- TI -- 1105469704 -- Fayber Estyben Díaz Tierradentro -- CC -- 1075795667 -- -- -- -- Analisis y desarollo de software -- 3413988 -- TARDE -- Taller ¿Quién es esta persona? Segmentación de Mercados Versión 2.0 2025 Desarrollado por Instructor Emprendimiento para el SENA como instrumento de apoyo a la formación.
A3: Lienzo Propuesta de Valor Diligencie únicamente las celdas en color AMARILLO
A5: Leer el Glosario de Términos de esta evidencia antes de plantear la propuesta de valor
B8: Que puede ofrecer Su negocio a su cliente | I8: Que desea o necesita su Cliente
B9: Productos o servicios que solucionan necesidades: | C9: Memorias RAM, Discos, Tarjetas graficas, Memorias USB, Procesadores | D9: Generadores de Alegrías o beneficios: | I9: Generadores de alegrías o beneficios: | L9: Trabajos que desea lograr su cliente:
D10: Se le ofreceran al cliente componentes de ultima tecnologia, de diferentes marcas, precios, calidades, todo esto para que se ajuste segun el presupuesto y las necesidades que desea satisfacer | I10: El cliente desea obtener equipos y repuestos de buena calidad que le permitan trabajar, estudiar o entretenerse sin problemas. Tambien desea recibir atencion rapida, precios accesibles y garantia en los productos y servicios. | L10: El cliente necesita realizar actividades como estudiar, trabajar, hacer tareas, navegar en internet, jugar y comunicarse de manera eficiente mediante su computador. También busca mantener sus equipos funcionando correctamente, actualizar componentes para mejorar el rendimiento y solucionar fallas técnicas sin perder información importante ni tiempo.
D17: Aliviadores de Dolores o frustraciones: | I17: Generadores de frustraciones o dolores:
D18: Con los porductos que le vamos a vender al cliente, su computador va a mejorar en rendimiento y capacidades, esto hara que el cliente se sienta satisfecho y pueda usar su computador sin problemas, ademas podra tenerlo actualizado con los ultimos componentes y accesorios lanzados. | I18: El cliente se siente frustado si su computador es lento o tiene problemas. Tambien le preocupa gastar mucho dinero en reparaciones o comprar productos de mala calidad. Otro problema es encontrar un negocio confiable donde si logren satisfacer sus preocupaciones
